Workbook

Sheet README
B1: FP&A Budget vs. Actual + Rolling Forecast Model
B2: Larkspur Home Goods, Inc. (fictional company) | FY2026 | Actuals closed through September, 9+3 forecast
B4: Prepared by | C4: [Your name]
B5: Disclaimer | C5: All company data is fictional and was simulated for portfolio purposes. No real company's financials are used.
B7: Company profile | C7: Mid-size direct-to-consumer and wholesale home goods brand, ~$21M annual revenue, three product lines: Kitchenware, Home Textiles, Home Decor & Lighting.
B9: TAB | C9: PURPOSE
B10: Dashboard | C10: Management dashboard: KPI tiles, revenue and EBITDA trend, EBITDA bridge, cost variances, key takeaways.
B11: BvA | C11: Budget vs. Actual P&L for the selected month, year-to-date, and full-year budget vs. 9+3 forecast. Change the month in the yellow cell.
B12: Variance Analysis | C12: Revenue price / volume / mix analysis, flexed-budget COGS analysis, and the Budget-to-Actual EBITDA bridge.
B13: Commentary | C13: Variance explanations by line item: driver, root cause, and how it is treated in the forecast.
B14: Forecast | C14: Rolling forecast: closed months pull actuals, open months are driver-based using the forecast levers on Assumptions.
B15: Budget | C15: Driver-based annual budget by month (units x price, standard costs, % of revenue and fixed opex).
B16: Actuals | C16: Monthly actuals as booked. Paste each new month here at close, then update 'Months of actuals closed' on Assumptions.
B17: Assumptions | C17: All budget drivers and forecast levers. Every hardcoded number in the model lives here or on Actuals.
B18: pbi_* tabs | C18: Star-schema tables for Power BI (2 fact tables, 5 dimension/lookup tables). Linked to the model by formula.
B20: COLOR LEGEND
B21: Blue text | C21: Hardcoded input you can change.
B22: Black text | C22: Formula on the same sheet.
B23: Green text | C23: Formula linking to another sheet.
B24: Yellow fill | C24: Key selector / lever / cell for you to fill in.
B26: CONVENTIONS
B27: Variance sign | C27: Variances are shown favorable = positive, unfavorable = negative (in parentheses) for every line. Revenue and profit: Actual - Budget. Costs: Budget - Actual.
B28: Month-end roll | C28: 1) Enter the month on Actuals. 2) Set Assumptions!B6 to the new month count. 3) Review forecast levers. 4) Pick the month on BvA. 5) Extend the Actual rows on pbi_fact tabs.
B29: Checks | C29: Variance Analysis has reconciliation checks (price + volume = total revenue variance; bridge ties to actual EBITDA). All should read 0.

Sheet Dashboard
B1: Larkspur Home Goods, Inc.: FY2026 Performance Dashboard
B2: ="Budget vs. Actual, YTD through "&BvA!B3&"-26 | Full-year outlook: 9+3 forecast | Fictional company" -> Budget vs. Actual, YTD through Sep-26 | Full-year outlook: 9+3 forecast | Fictional company
B4: YTD Revenue | D4: YTD Gross Margin | F4: YTD EBITDA | H4: YTD EBITDA Margin | J4: FY Forecast Revenue | L4: FY Forecast EBITDA
B5: =BvA!$I$17 -> 15479960 | D5: =BvA!$I$25 -> 0.46324202 | F5: =BvA!$I$37 -> 1532618 | H5: =BvA!$I$38 -> 0.099006587 | J5: =BvA!$P$17 -> 23440686 | L5: =BvA!$P$37 -> 3060196.3
B6: =TEXT(BvA!$K$17,"+0.0%;-0.0%")&" vs. budget" -> +1.0% vs. budget | D6: =TEXT(BvA!$J$25*100,"+0.0;-0.0")&" pts vs. budget" -> -1.3 pts vs. budget | F6: =TEXT(BvA!$K$37,"+0.0%;-0.0%")&" vs. budget" -> -12.8% vs. budget | H6: =TEXT(BvA!$J$38*100,"+0.0;-0.0")&" pts vs. budget" -> -1.6 pts vs. budget | J6: =TEXT(BvA!$R$17,"+0.0%;-0.0%")&" vs. budget" -> +1.7% vs. budget | L6: =TEXT(BvA!$R$37,"+0.0%;-0.0%")&" vs. budget" -> -8.8% vs. budget
H44: KEY TAKEAWAYS
H45: =Commentary!A5 -> YTD revenue of $15,479,960 is 1.0% ahead of budget ($158,360). Price contributed $14,612 and volume/mix $143,748.
H49: =Commentary!A6 -> YTD EBITDA of $1,532,618 is $224,666 (12.8%) below budget; EBITDA margin is 9.9% vs. 11.5% budgeted.
H53: =Commentary!A7 -> Gross margin of 46.3% compares with 47.6% in budget. COGS rate effects cost $212,582 (materials, overtime, freight) after adjusting for volume.
H57: =Commentary!A8 -> Full-year outlook (9+3): revenue $23,440,686 vs. budget $23,040,000; EBITDA $3,060,196 vs. budget $3,353,650 (-8.8%).
B62: Detail: BvA (full P&L), Variance Analysis (price/volume/mix, bridge), Commentary (drivers and actions).

Sheet BvA
A1: Budget vs. Actual
A2: Larkspur Home Goods, Inc. | FY2026 | Favorable variances positive, unfavorable in (parentheses)
A3: Reporting month | B3: Sep | C3: =MATCH(B3&"-26",Assumptions!$B$16:$M$16,0) -> 9 | D3: =IF(C3>Assumptions!$B$6,"Month not closed yet: pick a closed month","Month # (helper)") -> Month # (helper)
B5: =B3&"-26 (Month)" -> Sep-26 (Month) | H5: ="YTD through "&B3&"-26" -> YTD through Sep-26 | O5: Full Year FY2026
A6: ($ unless noted) | B6: Budget | C6: Actual | D6: Var $ | E6: Var % | F6: Status | H6: Budget | I6: Actual | J6: Var $ | K6: Var % | L6: Status | M6: Flag | O6: Budget | P6: Forecast (9+3) | Q6: Var $ | R6: Var % | S6: Status
A7: UNITS SOLD
A8: Kitchenware | B8: =INDEX(Budget!$B6:$M6,$C$3) -> 15300 | C8: =INDEX(Actuals!$B6:$M6,$C$3) -> 16677 | D8: =C8-B8 -> 1377 | E8: =IF(B8=0,0,D8/ABS(B8)) -> 0.09 | F8: =IF(ABS(E8)<0.005,"On plan",IF(D8>0,"Fav","Unfav")) -> Fav | H8: =SUMPRODUCT((Budget!$B$3:$M$3<=$C$3)*Budget!$B6:$M6) -> 119700 | I8: =SUMPRODUCT((Actuals!$B$3:$M$3<=$C$3)*Actuals!$B6:$M6) -> 127296 | J8: =I8-H8 -> 7596 | K8: =IF(H8=0,0,J8/ABS(H8)) -> 0.063458647 | L8: =IF(ABS(K8)<0.005,"On plan",IF(J8>0,"Fav","Unfav")) -> Fav | M8: =IF(AND(ABS(K8)>=Assumptions!$B$7,ABS(J8)>=Assumptions!$B$8),"Explain","") | O8: =Budget!$N6 -> 180000 | P8: =Forecast!$N6 -> 192420 | Q8: =P8-O8 -> 12420 | R8: =IF(O8=0,0,Q8/ABS(O8)) -> 0.069 | S8: =IF(ABS(R8)<0.005,"On plan",IF(Q8>0,"Fav","Unfav")) -> Fav
A9: Home Textiles | B9: =INDEX(Budget!$B7:$M7,$C$3) -> 10200 | C9: =INDEX(Actuals!$B7:$M7,$C$3) -> 9894 | D9: =C9-B9 -> -306 | E9: =IF(B9=0,0,D9/ABS(B9)) -> -0.03 | F9: =IF(ABS(E9)<0.005,"On plan",IF(D9>0,"Fav","Unfav")) -> Unfav | H9: =SUMPRODUCT((Budget!$B$3:$M$3<=$C$3)*Budget!$B7:$M7) -> 79800 | I9: =SUMPRODUCT((Actuals!$B$3:$M$3<=$C$3)*Actuals!$B7:$M7) -> 74544 | J9: =I9-H9 -> -5256 | K9: =IF(H9=0,0,J9/ABS(H9)) -> -0.065864662 | L9: =IF(ABS(K9)<0.005,"On plan",IF(J9>0,"Fav","Unfav")) -> Unfav | M9: =IF(AND(ABS(K9)>=Assumptions!$B$7,ABS(J9)>=Assumptions!$B$8),"Explain","") | O9: =Budget!$N7 -> 120000 | P9: =Forecast!$N7 -> 113136 | Q9: =P9-O9 -> -6864 | R9: =IF(O9=0,0,Q9/ABS(O9)) -> -0.0572 | S9: =IF(ABS(R9)<0.005,"On plan",IF(Q9>0,"Fav","Unfav")) -> Unfav
A10: Home Decor & Lighting | B10: =INDEX(Budget!$B8:$M8,$C$3) -> 5100 | C10: =INDEX(Actuals!$B8:$M8,$C$3) -> 5304 | D10: =C10-B10 -> 204 | E10: =IF(B10=0,0,D10/ABS(B10)) -> 0.04 | F10: =IF(ABS(E10)<0.005,"On plan",IF(D10>0,"Fav","Unfav")) -> Fav | H10: =SUMPRODUCT((Budget!$B$3:$M$3<=$C$3)*Budget!$B8:$M8) -> 39900 | I10: =SUMPRODUCT((Actuals!$B$3:$M$3<=$C$3)*Actuals!$B8:$M8) -> 40998 | J10: =I10-H10 -> 1098 | K10: =IF(H10=0,0,J10/ABS(H10)) -> 0.027518797 | L10: =IF(ABS(K10)<0.005,"On plan",IF(J10>0,"Fav","Unfav")) -> Fav | M10: =IF(AND(ABS(K10)>=Assumptions!$B$7,ABS(J10)>=Assumptions!$B$8),"Explain","") | O10: =Budget!$N8 -> 60000 | P10: =Forecast!$N8 -> 61902 | Q10: =P10-O10 -> 1902 | R10: =IF(O10=0,0,Q10/ABS(O10)) -> 0.0317 | S10: =IF(ABS(R10)<0.005,"On plan",IF(Q10>0,"Fav","Unfav")) -> Fav
A11: Total Units | B11: =INDEX(Budget!$B9:$M9,$C$3) -> 30600 | C11: =INDEX(Actuals!$B9:$M9,$C$3) -> 31875 | D11: =C11-B11 -> 1275 | E11: =IF(B11=0,0,D11/ABS(B11)) -> 0.041666667 | F11: =IF(ABS(E11)<0.005,"On plan",IF(D11>0,"Fav","Unfav")) -> Fav | H11: =SUMPRODUCT((Budget!$B$3:$M$3<=$C$3)*Budget!$B9:$M9) -> 239400 | I11: =SUMPRODUCT((Actuals!$B$3:$M$3<=$C$3)*Actuals!$B9:$M9) -> 242838 | J11: =I11-H11 -> 3438 | K11: =IF(H11=0,0,J11/ABS(H11)) -> 0.014360902 | L11: =IF(ABS(K11)<0.005,"On plan",IF(J11>0,"Fav","Unfav")) -> Fav | M11: =IF(AND(ABS(K11)>=Assumptions!$B$7,ABS(J11)>=Assumptions!$B$8),"Explain","") | O11: =Budget!$N9 -> 360000 | P11: =Forecast!$N9 -> 367458 | Q11: =P11-O11 -> 7458 | R11: =IF(O11=0,0,Q11/ABS(O11)) -> 0.020716667 | S11: =IF(ABS(R11)<0.005,"On plan",IF(Q11>0,"Fav","Unfav")) -> Fav
A13: REVENUE
A14: Kitchenware | B14: =INDEX(Budget!$B12:$M12,$C$3) -> 734400 | C14: =INDEX(Actuals!$B12:$M12,$C$3) -> 784486 | D14: =C14-B14 -> 50086 | E14: =IF(B14=0,0,D14/ABS(B14)) -> 0.068199891 | F14: =IF(ABS(E14)<0.005,"On plan",IF(D14>0,"Fav","Unfav")) -> Fav | H14: =SUMPRODUCT((Budget!$B$3:$M$3<=$C$3)*Budget!$B12:$M12) -> 5745600 | I14: =SUMPRODUCT((Actuals!$B$3:$M$3<=$C$3)*Actuals!$B12:$M12) -> 5989602 | J14: =I14-H14 -> 244002 | K14: =IF(H14=0,0,J14/ABS(H14)) -> 0.042467627 | L14: =IF(ABS(K14)<0.005,"On plan",IF(J14>0,"Fav","Unfav")) -> Fav | M14: =IF(AND(ABS(K14)>=Assumptions!$B$7,ABS(J14)>=Assumptions!$B$8),"Explain","") | O14: =Budget!$N12 -> 8640000 | P14: =Forecast!$N12 -> 9050430 | Q14: =P14-O14 -> 410430 | R14: =IF(O14=0,0,Q14/ABS(O14)) -> 0.047503472 | S14: =IF(ABS(R14)<0.005,"On plan",IF(Q14>0,"Fav","Unfav")) -> Fav
A15: Home Textiles | B15: =INDEX(Budget!$B13:$M13,$C$3) -> 663000 | C15: =INDEX(Actuals!$B13:$M13,$C$3) -> 639894 | D15: =C15-B15 -> -23106 | E15: =IF(B15=0,0,D15/ABS(B15)) -> -0.034850679 | F15: =IF(ABS(E15)<0.005,"On plan",IF(D15>0,"Fav","Unfav")) -> Unfav | H15: =SUMPRODUCT((Budget!$B$3:$M$3<=$C$3)*Budget!$B13:$M13) -> 5187000 | I15: =SUMPRODUCT((Actuals!$B$3:$M$3<=$C$3)*Actuals!$B13:$M13) -> 4852498 | J15: =I15-H15 -> -334502 | K15: =IF(H15=0,0,J15/ABS(H15)) -> -0.064488529 | L15: =IF(ABS(K15)<0.005,"On plan",IF(J15>0,"Fav","Unfav")) -> Unfav | M15: =IF(AND(ABS(K15)>=Assumptions!$B$7,ABS(J15)>=Assumptions!$B$8),"Explain","") -> Explain | O15: =Budget!$N13 -> 7800000 | P15: =Forecast!$N13 -> 7360978 | Q15: =P15-O15 -> -439022 | R15: =IF(O15=0,0,Q15/ABS(O15)) -> -0.056284872 | S15: =IF(ABS(R15)<0.005,"On plan",IF(Q15>0,"Fav","Unfav")) -> Unfav
A16: Home Decor & Lighting | B16: =INDEX(Budget!$B14:$M14,$C$3) -> 561000 | C16: =INDEX(Actuals!$B14:$M14,$C$3) -> 606778 | D16: =C16-B16 -> 45778 | E16: =IF(B16=0,0,D16/ABS(B16)) -> 0.081600713 | F16: =IF(ABS(E16)<0.005,"On plan",IF(D16>0,"Fav","Unfav")) -> Fav | H16: =SUMPRODUCT((Budget!$B$3:$M$3<=$C$3)*Budget!$B14:$M14) -> 4389000 | I16: =SUMPRODUCT((Actuals!$B$3:$M$3<=$C$3)*Actuals!$B14:$M14) -> 4637860 | J16: =I16-H16 -> 248860 | K16: =IF(H16=0,0,J16/ABS(H16)) -> 0.056700843 | L16: =IF(ABS(K16)<0.005,"On plan",IF(J16>0,"Fav","Unfav")) -> Fav | M16: =IF(AND(ABS(K16)>=Assumptions!$B$7,ABS(J16)>=Assumptions!$B$8),"Explain","") -> Explain | O16: =Budget!$N14 -> 6600000 | P16: =Forecast!$N14 -> 7029277.6 | Q16: =P16-O16 -> 429277.6 | R16: =IF(O16=0,0,Q16/ABS(O16)) -> 0.065042061 | S16: =IF(ABS(R16)<0.005,"On plan",IF(Q16>0,"Fav","Unfav")) -> Fav
A17: Total Revenue | B17: =INDEX(Budget!$B15:$M15,$C$3) -> 1958400 | C17: =INDEX(Actuals!$B15:$M15,$C$3) -> 2031158 | D17: =C17-B17 -> 72758 | E17: =IF(B17=0,0,D17/ABS(B17)) -> 0.037151757 | F17: =IF(ABS(E17)<0.005,"On plan",IF(D17>0,"Fav","Unfav")) -> Fav | H17: =SUMPRODUCT((Budget!$B$3:$M$3<=$C$3)*Budget!$B15:$M15) -> 15321600 | I17: =SUMPRODUCT((Actuals!$B$3:$M$3<=$C$3)*Actuals!$B15:$M15) -> 15479960 | J17: =I17-H17 -> 158360 | K17: =IF(H17=0,0,J17/ABS(H17)) -> 0.010335735 | L17: =IF(ABS(K17)<0.005,"On plan",IF(J17>0,"Fav","Unfav")) -> Fav | M17: =IF(AND(ABS(K17)>=Assumptions!$B$7,ABS(J17)>=Assumptions!$B$8),"Explain","") | O17: =Budget!$N15 -> 23040000 | P17: =Forecast!$N15 -> 23440686 | Q17: =P17-O17 -> 400685.6 | R17: =IF(O17=0,0,Q17/ABS(O17)) -> 0.017390868 | S17: =IF(ABS(R17)<0.005,"On plan",IF(Q17>0,"Fav","Unfav")) -> Fav
A19: COST OF GOODS SOLD
A20: Materials | B20: =INDEX(Budget!$B18:$M18,$C$3) -> 714000 | C20: =INDEX(Actuals!$B18:$M18,$C$3) -> 754390 | D20: =B20-C20 -> -40390 | E20: =IF(B20=0,0,D20/ABS(B20)) -> -0.056568627 | F20: =IF(ABS(E20)<0.005,"On plan",IF(D20>0,"Fav","Unfav")) -> Unfav | H20: =SUMPRODUCT((Budget!$B$3:$M$3<=$C$3)*Budget!$B18:$M18) -> 5586000 | I20: =SUMPRODUCT((Actuals!$B$3:$M$3<=$C$3)*Actuals!$B18:$M18) -> 5709304 | J20: =H20-I20 -> -123304 | K20: =IF(H20=0,0,J20/ABS(H20)) -> -0.022073756 | L20: =IF(ABS(K20)<0.005,"On plan",IF(J20>0,"Fav","Unfav")) -> Unfav | M20: =IF(AND(ABS(K20)>=Assumptions!$B$7,ABS(J20)>=Assumptions!$B$8),"Explain","") | O20: =Budget!$N18 -> 8400000 | P20: =Forecast!$N18 -> 8662018.1 | Q20: =O20-P20 -> -262018.12 | R20: =IF(O20=0,0,Q20/ABS(O20)) -> -0.031192633 | S20: =IF(ABS(R20)<0.005,"On plan",IF(Q20>0,"Fav","Unfav")) -> Unfav
A21: Direct Labor | B21: =INDEX(Budget!$B19:$M19,$C$3) -> 224400 | C21: =INDEX(Actuals!$B19:$M19,$C$3) -> 236119 | D21: =B21-C21 -> -11719 | E21: =IF(B21=0,0,D21/ABS(B21)) -> -0.052223708 | F21: =IF(ABS(E21)<0.005,"On plan",IF(D21>0,"Fav","Unfav")) -> Unfav | H21: =SUMPRODUCT((Budget!$B$3:$M$3<=$C$3)*Budget!$B19:$M19) -> 1755600 | I21: =SUMPRODUCT((Actuals!$B$3:$M$3<=$C$3)*Actuals!$B19:$M19) -> 1803614 | J21: =H21-I21 -> -48014 | K21: =IF(H21=0,0,J21/ABS(H21)) -> -0.027349054 | L21: =IF(ABS(K21)<0.005,"On plan",IF(J21>0,"Fav","Unfav")) -> Unfav | M21: =IF(AND(ABS(K21)>=Assumptions!$B$7,ABS(J21)>=Assumptions!$B$8),"Explain","") | O21: =Budget!$N19 -> 2640000 | P21: =Forecast!$N19 -> 2727844.2 | Q21: =O21-P21 -> -87844.16 | R21: =IF(O21=0,0,Q21/ABS(O21)) -> -0.033274303 | S21: =IF(ABS(R21)<0.005,"On plan",IF(Q21>0,"Fav","Unfav")) -> Unfav
A22: Freight & Fulfillment | B22: =INDEX(Budget!$B20:$M20,$C$3) -> 88128 | C22: =INDEX(Actuals!$B20:$M20,$C$3) -> 103589 | D22: =B22-C22 -> -15461 | E22: =IF(B22=0,0,D22/ABS(B22)) -> -0.175438 | F22: =IF(ABS(E22)<0.005,"On plan",IF(D22>0,"Fav","Unfav")) -> Unfav | H22: =SUMPRODUCT((Budget!$B$3:$M$3<=$C$3)*Budget!$B20:$M20) -> 689472 | I22: =SUMPRODUCT((Actuals!$B$3:$M$3<=$C$3)*Actuals!$B20:$M20) -> 796074 | J22: =H22-I22 -> -106602 | K22: =IF(H22=0,0,J22/ABS(H22)) -> -0.15461397 | L22: =IF(ABS(K22)<0.005,"On plan",IF(J22>0,"Fav","Unfav")) -> Unfav | M22: =IF(AND(ABS(K22)>=Assumptions!$B$7,ABS(J22)>=Assumptions!$B$8),"Explain","") -> Explain | O22: =Budget!$N20 -> 1036800 | P22: =Forecast!$N20 -> 1194110.3 | Q22: =O22-P22 -> -157310.28 | R22: =IF(O22=0,0,Q22/ABS(O22)) -> -0.15172674 | S22: =IF(ABS(R22)<0.005,"On plan",IF(Q22>0,"Fav","Unfav")) -> Unfav
A23: Total COGS | B23: =INDEX(Budget!$B21:$M21,$C$3) -> 1026528 | C23: =INDEX(Actuals!$B21:$M21,$C$3) -> 1094098 | D23: =B23-C23 -> -67570 | E23: =IF(B23=0,0,D23/ABS(B23)) -> -0.065823826 | F23: =IF(ABS(E23)<0.005,"On plan",IF(D23>0,"Fav","Unfav")) -> Unfav | H23: =SUMPRODUCT((Budget!$B$3:$M$3<=$C$3)*Budget!$B21:$M21) -> 8031072 | I23: =SUMPRODUCT((Actuals!$B$3:$M$3<=$C$3)*Actuals!$B21:$M21) -> 8308992 | J23: =H23-I23 -> -277920 | K23: =IF(H23=0,0,J23/ABS(H23)) -> -0.034605592 | L23: =IF(ABS(K23)<0.005,"On plan",IF(J23>0,"Fav","Unfav")) -> Unfav | M23: =IF(AND(ABS(K23)>=Assumptions!$B$7,ABS(J23)>=Assumptions!$B$8),"Explain","") | O23: =Budget!$N21 -> 12076800 | P23: =Forecast!$N21 -> 12583973 | Q23: =O23-P23 -> -507172.56 | R23: =IF(O23=0,0,Q23/ABS(O23)) -> -0.041995608 | S23: =IF(ABS(R23)<0.005,"On plan",IF(Q23>0,"Fav","Unfav")) -> Unfav
A24: Gross Profit | B24: =INDEX(Budget!$B22:$M22,$C$3) -> 931872 | C24: =INDEX(Actuals!$B22:$M22,$C$3) -> 937060 | D24: =C24-B24 -> 5188 | E24: =IF(B24=0,0,D24/ABS(B24)) -> 0.0055672882 | F24: =IF(ABS(E24)<0.005,"On plan",IF(D24>0,"Fav","Unfav")) -> Fav | H24: =SUMPRODUCT((Budget!$B$3:$M$3<=$C$3)*Budget!$B22:$M22) -> 7290528 | I24: =SUMPRODUCT((Actuals!$B$3:$M$3<=$C$3)*Actuals!$B22:$M22) -> 7170968 | J24: =I24-H24 -> -119560 | K24: =IF(H24=0,0,J24/ABS(H24)) -> -0.016399361 | L24: =IF(ABS(K24)<0.005,"On plan",IF(J24>0,"Fav","Unfav")) -> Unfav | M24: =IF(AND(ABS(K24)>=Assumptions!$B$7,ABS(J24)>=Assumptions!$B$8),"Explain","") | O24: =Budget!$N22 -> 10963200 | P24: =Forecast!$N22 -> 10856713 | Q24: =P24-O24 -> -106486.96 | R24: =IF(O24=0,0,Q24/ABS(O24)) -> -0.0097131276 | S24: =IF(ABS(R24)<0.005,"On plan",IF(Q24>0,"Fav","Unfav")) -> Unfav
A25: Gross Margin % | B25: =IF(B17=0,0,B24/B17) -> 0.47583333 | C25: =IF(C17=0,0,C24/C17) -> 0.46134274 | D25: =C25-B25 -> -0.014490592 | F25: =IF(ABS(D25)<0.0005,"On plan",IF(D25>0,"Fav","Unfav")) -> Unfav | H25: =IF(H17=0,0,H24/H17) -> 0.47583333 | I25: =IF(I17=0,0,I24/I17) -> 0.46324202 | J25: =I25-H25 -> -0.012591309 | L25: =IF(ABS(J25)<0.0005,"On plan",IF(J25>0,"Fav","Unfav")) -> Unfav | O25: =IF(O17=0,0,O24/O17) -> 0.47583333 | P25: =IF(P17=0,0,P24/P17) -> 0.4631568 | Q25: =P25-O25 -> -0.012676529 | S25: =IF(ABS(Q25)<0.0005,"On plan",IF(Q25>0,"Fav","Unfav")) -> Unfav
A27: OPERATING EXPENSES
A28: Salaries & Benefits | B28: =INDEX(Budget!$B26:$M26,$C$3) -> 293550 | C28: =INDEX(Actuals!$B26:$M26,$C$3) -> 295020 | D28: =B28-C28 -> -1470 | E28: =IF(B28=0,0,D28/ABS(B28)) -> -0.0050076648 | F28: =IF(ABS(E28)<0.005,"On plan",IF(D28>0,"Fav","Unfav")) -> Unfav | H28: =SUMPRODUCT((Budget!$B$3:$M$3<=$C$3)*Budget!$B26:$M26) -> 2616300 | I28: =SUMPRODUCT((Actuals!$B$3:$M$3<=$C$3)*Actuals!$B26:$M26) -> 2552200 | J28: =H28-I28 -> 64100 | K28: =IF(H28=0,0,J28/ABS(H28)) -> 0.024500248 | L28: =IF(ABS(K28)<0.005,"On plan",IF(J28>0,"Fav","Unfav")) -> Fav | M28: =IF(AND(ABS(K28)>=Assumptions!$B$7,ABS(J28)>=Assumptions!$B$8),"Explain","") | O28: =Budget!$N26 -> 3496950 | P28: =Forecast!$N26 -> 3446200 | Q28: =O28-P28 -> 50750 | R28: =IF(O28=0,0,Q28/ABS(O28)) -> 0.014512647 | S28: =IF(ABS(R28)<0.005,"On plan",IF(Q28>0,"Fav","Unfav")) -> Fav
A29: Marketing & Advertising | B29: =INDEX(Budget!$B27:$M27,$C$3) -> 176256 | C29: =INDEX(Actuals!$B27:$M27,$C$3) -> 186800 | D29: =B29-C29 -> -10544 | E29: =IF(B29=0,0,D29/ABS(B29)) -> -0.059822077 | F29: =IF(ABS(E29)<0.005,"On plan",IF(D29>0,"Fav","Unfav")) -> Unfav | H29: =SUMPRODUCT((Budget!$B$3:$M$3<=$C$3)*Budget!$B27:$M27) -> 1378944 | I29: =SUMPRODUCT((Actuals!$B$3:$M$3<=$C$3)*Actuals!$B27:$M27) -> 1481700 | J29: =H29-I29 -> -102756 | K29: =IF(H29=0,0,J29/ABS(H29)) -> -0.074517892 | L29: =IF(ABS(K29)<0.005,"On plan",IF(J29>0,"Fav","Unfav")) -> Unfav | M29: =IF(AND(ABS(K29)>=Assumptions!$B$7,ABS(J29)>=Assumptions!$B$8),"Explain","") -> Explain | O29: =Budget!$N27 -> 2073600 | P29: =Forecast!$N27 -> 2214086.8 | Q29: =O29-P29 -> -140486.76 | R29: =IF(O29=0,0,Q29/ABS(O29)) -> -0.067750171 | S29: =IF(ABS(R29)<0.005,"On plan",IF(Q29>0,"Fav","Unfav")) -> Unfav
A30: Rent & Utilities | B30: =INDEX(Budget!$B28:$M28,$C$3) -> 62000 | C30: =INDEX(Actuals!$B28:$M28,$C$3) -> 64100 | D30: =B30-C30 -> -2100 | E30: =IF(B30=0,0,D30/ABS(B30)) -> -0.033870968 | F30: =IF(ABS(E30)<0.005,"On plan",IF(D30>0,"Fav","Unfav")) -> Unfav | H30: =SUMPRODUCT((Budget!$B$3:$M$3<=$C$3)*Budget!$B28:$M28) -> 558000 | I30: =SUMPRODUCT((Actuals!$B$3:$M$3<=$C$3)*Actuals!$B28:$M28) -> 564300 | J30: =H30-I30 -> -6300 | K30: =IF(H30=0,0,J30/ABS(H30)) -> -0.011290323 | L30: =IF(ABS(K30)<0.005,"On plan",IF(J30>0,"Fav","Unfav")) -> Unfav | M30: =IF(AND(ABS(K30)>=Assumptions!$B$7,ABS(J30)>=Assumptions!$B$8),"Explain","") | O30: =Budget!$N28 -> 744000 | P30: =Forecast!$N28 -> 756600 | Q30: =O30-P30 -> -12600 | R30: =IF(O30=0,0,Q30/ABS(O30)) -> -0.016935484 | S30: =IF(ABS(R30)<0.005,"On plan",IF(Q30>0,"Fav","Unfav")) -> Unfav
A31: Software & IT | B31: =INDEX(Budget!$B29:$M29,$C$3) -> 38000 | C31: =INDEX(Actuals!$B29:$M29,$C$3) -> 44720 | D31: =B31-C31 -> -6720 | E31: =IF(B31=0,0,D31/ABS(B31)) -> -0.17684211 | F31: =IF(ABS(E31)<0.005,"On plan",IF(D31>0,"Fav","Unfav")) -> Unfav | H31: =SUMPRODUCT((Budget!$B$3:$M$3<=$C$3)*Budget!$B29:$M29) -> 342000 | I31: =SUMPRODUCT((Actuals!$B$3:$M$3<=$C$3)*Actuals!$B29:$M29) -> 375970 | J31: =H31-I31 -> -33970 | K31: =IF(H31=0,0,J31/ABS(H31)) -> -0.099327485 | L31: =IF(ABS(K31)<0.005,"On plan",IF(J31>0,"Fav","Unfav")) -> Unfav | M31: =IF(AND(ABS(K31)>=Assumptions!$B$7,ABS(J31)>=Assumptions!$B$8),"Explain","") -> Explain | O31: =Budget!$N29 -> 456000 | P31: =Forecast!$N29 -> 510070 | Q31: =O31-P31 -> -54070 | R31: =IF(O31=0,0,Q31/ABS(O31)) -> -0.11857456 | S31: =IF(ABS(R31)<0.005,"On plan",IF(Q31>0,"Fav","Unfav")) -> Unfav
A32: Professional Fees | B32: =INDEX(Budget!$B30:$M30,$C$3) -> 22000 | C32: =INDEX(Actuals!$B30:$M30,$C$3) -> 23500 | D32: =B32-C32 -> -1500 | E32: =IF(B32=0,0,D32/ABS(B32)) -> -0.068181818 | F32: =IF(ABS(E32)<0.005,"On plan",IF(D32>0,"Fav","Unfav")) -> Unfav | H32: =SUMPRODUCT((Budget!$B$3:$M$3<=$C$3)*Budget!$B30:$M30) -> 233000 | I32: =SUMPRODUCT((Actuals!$B$3:$M$3<=$C$3)*Actuals!$B30:$M30) -> 277800 | J32: =H32-I32 -> -44800 | K32: =IF(H32=0,0,J32/ABS(H32)) -> -0.19227468 | L32: =IF(ABS(K32)<0.005,"On plan",IF(J32>0,"Fav","Unfav")) -> Unfav | M32: =IF(AND(ABS(K32)>=Assumptions!$B$7,ABS(J32)>=Assumptions!$B$8),"Explain","") -> Explain | O32: =Budget!$N30 -> 299000 | P32: =Forecast!$N30 -> 349800 | Q32: =O32-P32 -> -50800 | R32: =IF(O32=0,0,Q32/ABS(O32)) -> -0.16989967 | S32: =IF(ABS(R32)<0.005,"On plan",IF(Q32>0,"Fav","Unfav")) -> Unfav
A33: Travel & Entertainment | B33: =INDEX(Budget!$B31:$M31,$C$3) -> 15000 | C33: =INDEX(Actuals!$B31:$M31,$C$3) -> 12600 | D33: =B33-C33 -> 2400 | E33: =IF(B33=0,0,D33/ABS(B33)) -> 0.16 | F33: =IF(ABS(E33)<0.005,"On plan",IF(D33>0,"Fav","Unfav")) -> Fav | H33: =SUMPRODUCT((Budget!$B$3:$M$3<=$C$3)*Budget!$B31:$M31) -> 135000 | I33: =SUMPRODUCT((Actuals!$B$3:$M$3<=$C$3)*Actuals!$B31:$M31) -> 109400 | J33: =H33-I33 -> 25600 | K33: =IF(H33=0,0,J33/ABS(H33)) -> 0.18962963 | L33: =IF(ABS(K33)<0.005,"On plan",IF(J33>0,"Fav","Unfav")) -> Fav | M33: =IF(AND(ABS(K33)>=Assumptions!$B$7,ABS(J33)>=Assumptions!$B$8),"Explain","") -> Explain | O33: =Budget!$N31 -> 180000 | P33: =Forecast!$N31 -> 148400 | Q33: =O33-P33 -> 31600 | R33: =IF(O33=0,0,Q33/ABS(O33)) -> 0.17555556 | S33: =IF(ABS(R33)<0.005,"On plan",IF(Q33>0,"Fav","Unfav")) -> Fav
A34: Insurance | B34: =INDEX(Budget!$B32:$M32,$C$3) -> 12000 | C34: =INDEX(Actuals!$B32:$M32,$C$3) -> 12960 | D34: =B34-C34 -> -960 | E34: =IF(B34=0,0,D34/ABS(B34)) -> -0.08 | F34: =IF(ABS(E34)<0.005,"On plan",IF(D34>0,"Fav","Unfav")) -> Unfav | H34: =SUMPRODUCT((Budget!$B$3:$M$3<=$C$3)*Budget!$B32:$M32) -> 108000 | I34: =SUMPRODUCT((Actuals!$B$3:$M$3<=$C$3)*Actuals!$B32:$M32) -> 110880 | J34: =H34-I34 -> -2880 | K34: =IF(H34=0,0,J34/ABS(H34)) -> -0.026666667 | L34: =IF(ABS(K34)<0.005,"On plan",IF(J34>0,"Fav","Unfav")) -> Unfav | M34: =IF(AND(ABS(K34)>=Assumptions!$B$7,ABS(J34)>=Assumptions!$B$8),"Explain","") | O34: =Budget!$N32 -> 144000 | P34: =Forecast!$N32 -> 149760 | Q34: =O34-P34 -> -5760 | R34: =IF(O34=0,0,Q34/ABS(O34)) -> -0.04 | S34: =IF(ABS(R34)<0.005,"On plan",IF(Q34>0,"Fav","Unfav")) -> Unfav
A35: Other G&A | B35: =INDEX(Budget!$B33:$M33,$C$3) -> 18000 | C35: =INDEX(Actuals!$B33:$M33,$C$3) -> 19000 | D35: =B35-C35 -> -1000 | E35: =IF(B35=0,0,D35/ABS(B35)) -> -0.055555556 | F35: =IF(ABS(E35)<0.005,"On plan",IF(D35>0,"Fav","Unfav")) -> Unfav | H35: =SUMPRODUCT((Budget!$B$3:$M$3<=$C$3)*Budget!$B33:$M33) -> 162000 | I35: =SUMPRODUCT((Actuals!$B$3:$M$3<=$C$3)*Actuals!$B33:$M33) -> 166100 | J35: =H35-I35 -> -4100 | K35: =IF(H35=0,0,J35/ABS(H35)) -> -0.025308642 | L35: =IF(ABS(K35)<0.005,"On plan",IF(J35>0,"Fav","Unfav")) -> Unfav | M35: =IF(AND(ABS(K35)>=Assumptions!$B$7,ABS(J35)>=Assumptions!$B$8),"Explain","") | O35: =Budget!$N33 -> 216000 | P35: =Forecast!$N33 -> 221600 | Q35: =O35-P35 -> -5600 | R35: =IF(O35=0,0,Q35/ABS(O35)) -> -0.025925926 | S35: =IF(ABS(R35)<0.005,"On plan",IF(Q35>0,"Fav","Unfav")) -> Unfav
A36: Total Operating Expenses | B36: =INDEX(Budget!$B34:$M34,$C$3) -> 636806 | C36: =INDEX(Actuals!$B34:$M34,$C$3) -> 658700 | D36: =B36-C36 -> -21894 | E36: =IF(B36=0,0,D36/ABS(B36)) -> -0.034380957 | F36: =IF(ABS(E36)<0.005,"On plan",IF(D36>0,"Fav","Unfav")) -> Unfav | H36: =SUMPRODUCT((Budget!$B$3:$M$3<=$C$3)*Budget!$B34:$M34) -> 5533244 | I36: =SUMPRODUCT((Actuals!$B$3:$M$3<=$C$3)*Actuals!$B34:$M34) -> 5638350 | J36: =H36-I36 -> -105106 | K36: =IF(H36=0,0,J36/ABS(H36)) -> -0.018995367 | L36: =IF(ABS(K36)<0.005,"On plan",IF(J36>0,"Fav","Unfav")) -> Unfav | M36: =IF(AND(ABS(K36)>=Assumptions!$B$7,ABS(J36)>=Assumptions!$B$8),"Explain","") | O36: =Budget!$N34 -> 7609550 | P36: =Forecast!$N34 -> 7796516.8 | Q36: =O36-P36 -> -186966.76 | R36: =IF(O36=0,0,Q36/ABS(O36)) -> -0.024570015 | S36: =IF(ABS(R36)<0.005,"On plan",IF(Q36>0,"Fav","Unfav")) -> Unfav
A37: EBITDA | B37: =INDEX(Budget!$B35:$M35,$C$3) -> 295066 | C37: =INDEX(Actuals!$B35:$M35,$C$3) -> 278360 | D37: =C37-B37 -> -16706 | E37: =IF(B37=0,0,D37/ABS(B37)) -> -0.056617841 | F37: =IF(ABS(E37)<0.005,"On plan",IF(D37>0,"Fav","Unfav")) -> Unfav | H37: =SUMPRODUCT((Budget!$B$3:$M$3<=$C$3)*Budget!$B35:$M35) -> 1757284 | I37: =SUMPRODUCT((Actuals!$B$3:$M$3<=$C$3)*Actuals!$B35:$M35) -> 1532618 | J37: =I37-H37 -> -224666 | K37: =IF(H37=0,0,J37/ABS(H37)) -> -0.12784843 | L37: =IF(ABS(K37)<0.005,"On plan",IF(J37>0,"Fav","Unfav")) -> Unfav | M37: =IF(AND(ABS(K37)>=Assumptions!$B$7,ABS(J37)>=Assumptions!$B$8),"Explain","") -> Explain | O37: =Budget!$N35 -> 3353650 | P37: =Forecast!$N35 -> 3060196.3 | Q37: =P37-O37 -> -293453.72 | R37: =IF(O37=0,0,Q37/ABS(O37)) -> -0.087502785 | S37: =IF(ABS(R37)<0.005,"On plan",IF(Q37>0,"Fav","Unfav")) -> Unfav
A38: EBITDA Margin % | B38: =IF(B17=0,0,B37/B17) -> 0.15066687 | C38: =IF(C17=0,0,C37/C17) -> 0.13704498 | D38: =C38-B38 -> -0.013621895 | F38: =IF(ABS(D38)<0.0005,"On plan",IF(D38>0,"Fav","Unfav")) -> Unfav | H38: =IF(H17=0,0,H37/H17) -> 0.11469324 | I38: =IF(I17=0,0,I37/I17) -> 0.099006587 | J38: =I38-H38 -> -0.015686657 | L38: =IF(ABS(J38)<0.0005,"On plan",IF(J38>0,"Fav","Unfav")) -> Unfav | O38: =IF(O17=0,0,O37/O17) -> 0.14555773 | P38: =IF(P17=0,0,P37/P17) -> 0.13055063 | Q38: =P38-O38 -> -0.015007095 | S38: =IF(ABS(Q38)<0.0005,"On plan",IF(Q38>0,"Fav","Unfav")) -> Unfav
A40: Var $ sign convention: revenue, gross profit, EBITDA = Actual - Budget; cost lines = Budget - Actual. Margin rows show the change in percentage points.

Sheet Variance Analysis
A1: Variance Analysis
A2: Larkspur Home Goods, Inc. | Year-to-date, follows the reporting month on BvA
A3: ="Period: YTD through "&BvA!B3&"-26" -> Period: YTD through Sep-26
A5: 1. REVENUE: PRICE / VOLUME / MIX | B5: Budget units | C5: Actual units | D5: Budget price | E5: Actual price | F5: Volume variance | G5: Price variance | H5: Total variance | I5: Check vs. BvA
A6: Kitchenware | B6: =BvA!$H$8 -> 119700 | C6: =BvA!$I$8 -> 127296 | D6: =IF(B6=0,0,BvA!$H$14/B6) -> 48 | E6: =IF(C6=0,0,BvA!$I$14/C6) -> 47.052555 | F6: =(C6-B6)*D6 -> 364608 | G6: =(E6-D6)*C6 -> -120606 | H6: =F6+G6 -> 244002 | I6: =ROUND(H6-BvA!$J$14,0) -> 0
A7: Home Textiles | B7: =BvA!$H$9 -> 79800 | C7: =BvA!$I$9 -> 74544 | D7: =IF(B7=0,0,BvA!$H$15/B7) -> 65 | E7: =IF(C7=0,0,BvA!$I$15/C7) -> 65.095756 | F7: =(C7-B7)*D7 -> -341640 | G7: =(E7-D7)*C7 -> 7138 | H7: =F7+G7 -> -334502 | I7: =ROUND(H7-BvA!$J$15,0) -> 0
A8: Home Decor & Lighting | B8: =BvA!$H$10 -> 39900 | C8: =BvA!$I$10 -> 40998 | D8: =IF(B8=0,0,BvA!$H$16/B8) -> 110 | E8: =IF(C8=0,0,BvA!$I$16/C8) -> 113.12405 | F8: =(C8-B8)*D8 -> 120780 | G8: =(E8-D8)*C8 -> 128080 | H8: =F8+G8 -> 248860 | I8: =ROUND(H8-BvA!$J$16,0) -> 0
A9: Total | B9: =SUM(B6:B8) -> 239400 | C9: =SUM(C6:C8) -> 242838 | D9: =IF(B9=0,0,BvA!$H$17/B9) -> 64 | E9: =IF(C9=0,0,BvA!$I$17/C9) -> 63.746036 | F9: =SUM(F6:F8) -> 143748 | G9: =SUM(G6:G8) -> 14612 | H9: =SUM(H6:H8) -> 158360 | I9: =ROUND(H9-BvA!$J$17,0) -> 0
A10: of which pure volume (total unit change x budget avg. price) | F10: =(C9-B9)*D9 -> 220032
A11: of which mix (shift between product lines) | F11: =F9-F10 -> -76284
A12: Volume = (actual units - budget units) x budget price. Price = (actual price - budget price) x actual units.
A14: 2. COST OF GOODS SOLD: FLEXED BUDGET | B14: Budget | C14: Flexed budget (actual volume) | D14: Actual | E14: Volume effect | F14: Rate / efficiency effect | G14: Total variance | H14: Check vs. BvA
A15: Materials | B15: =BvA!$H$20 -> 5586000 | C15: =SUMPRODUCT(C6:C8,Assumptions!$D$11:$D$13) -> 5634006 | D15: =BvA!$I$20 -> 5709304 | E15: =B15-C15 -> -48006 | F15: =C15-D15 -> -75298 | G15: =E15+F15 -> -123304 | H15: =ROUND(G15-BvA!$J$20,0) -> 0
A16: Direct Labor | B16: =BvA!$H$21 -> 1755600 | C16: =SUMPRODUCT(C6:C8,Assumptions!$E$11:$E$13) -> 1765806 | D16: =BvA!$I$21 -> 1803614 | E16: =B16-C16 -> -10206 | F16: =C16-D16 -> -37808 | G16: =E16+F16 -> -48014 | H16: =ROUND(G16-BvA!$J$21,0) -> 0
A17: Freight & Fulfillment | B17: =BvA!$H$22 -> 689472 | C17: =BvA!$I$17*Assumptions!$B$20 -> 696598.2 | D17: =BvA!$I$22 -> 796074 | E17: =B17-C17 -> -7126.2 | F17: =C17-D17 -> -99475.8 | G17: =E17+F17 -> -106602 | H17: =ROUND(G17-BvA!$J$22,0) -> 0
A18: Total COGS | B18: =SUM(B15:B17) -> 8031072 | C18: =SUM(C15:C17) -> 8096410.2 | D18: =SUM(D15:D17) -> 8308992 | E18: =SUM(E15:E17) -> -65338.2 | F18: =SUM(F15:F17) -> -212581.8 | G18: =SUM(G15:G17) -> -277920
A19: Flexed budget = what the budget would have been at actual volume (standard cost x actual units; budget freight % x actual revenue).
A21: 3. EBITDA BRIDGE: BUDGET TO ACTUAL | B21: Amount | C21: Cumulative | D21: Chart: base | E21: Chart: total | F21: Chart: increase | G21: Chart: decrease | H21: Chart: label
A22: Budget EBITDA | B22: =BvA!$H$37 -> 1757284 | C22: =B22 -> 1757284 | D22: 0 | E22: =B22 -> 1757284 | F22: 0 | G22: 0 | H22: Budget
A23: Price | B23: =G9 -> 14612 | C23: =C22+B23 -> 1771896 | D23: =MIN(C22,C23) -> 1757284 | E23: 0 | F23: =MAX(B23,0) -> 14612 | G23: =MAX(-B23,0) -> 0 | H23: Price
A24: Volume & mix (net of std. variable cost) | B24: =F9+E18 -> 78409.8 | C24: =C23+B24 -> 1850305.8 | D24: =MIN(C23,C24) -> 1771896 | E24: 0 | F24: =MAX(B24,0) -> 78409.8 | G24: =MAX(-B24,0) -> 0 | H24: Volume & mix
A25: Material cost rate | B25: =F15 -> -75298 | C25: =C24+B25 -> 1775007.8 | D25: =MIN(C24,C25) -> 1775007.8 | E25: 0 | F25: =MAX(B25,0) -> 0 | G25: =MAX(-B25,0) -> 75298 | H25: Material rate
A26: Labor rate & overtime | B26: =F16 -> -37808 | C26: =C25+B26 -> 1737199.8 | D26: =MIN(C25,C26) -> 1737199.8 | E26: 0 | F26: =MAX(B26,0) -> 0 | G26: =MAX(-B26,0) -> 37808 | H26: Labor rate
A27: Freight rate | B27: =F17 -> -99475.8 | C27: =C26+B27 -> 1637724 | D27: =MIN(C26,C27) -> 1637724 | E27: 0 | F27: =MAX(B27,0) -> 0 | G27: =MAX(-B27,0) -> 99475.8 | H27: Freight rate
A28: Salaries & Benefits | B28: =BvA!$J$28 -> 64100 | C28: =C27+B28 -> 1701824 | D28: =MIN(C27,C28) -> 1637724 | E28: 0 | F28: =MAX(B28,0) -> 64100 | G28: =MAX(-B28,0) -> 0 | H28: Salaries
A29: Marketing & Advertising | B29: =BvA!$J$29 -> -102756 | C29: =C28+B29 -> 1599068 | D29: =MIN(C28,C29) -> 1599068 | E29: 0 | F29: =MAX(B29,0) -> 0 | G29: =MAX(-B29,0) -> 102756 | H29: Marketing
A30: Other operating expenses | B30: =BvA!$J$36-BvA!$J$28-BvA!$J$29 -> -66450 | C30: =C29+B30 -> 1532618 | D30: =MIN(C29,C30) -> 1532618 | E30: 0 | F30: =MAX(B30,0) -> 0 | G30: =MAX(-B30,0) -> 66450 | H30: Other opex
A31: Actual EBITDA | B31: =C30 -> 1532618 | C31: =B31 -> 1532618 | D31: 0 | E31: =B31 -> 1532618 | F31: 0 | G31: 0 | H31: Actual
A32: Check: bridge ends at actual EBITDA on BvA (should be 0) | B32: =ROUND(B31-BvA!$I$37,0) -> 0
A34: 4. YTD COST VARIANCES BY LINE (favorable + / unfavorable -) | B34: Var $ | C34: Var % | D34: Chart: favorable | E34: Chart: unfavorable
A35: =BvA!$A$20 -> Materials | B35: =BvA!$J$20 -> -123304 | C35: =BvA!$K$20 -> -0.022073756 | D35: =MAX(B35,0) -> 0 | E35: =MIN(B35,0) -> -123304
A36: =BvA!$A$21 -> Direct Labor | B36: =BvA!$J$21 -> -48014 | C36: =BvA!$K$21 -> -0.027349054 | D36: =MAX(B36,0) -> 0 | E36: =MIN(B36,0) -> -48014
A37: =BvA!$A$22 -> Freight & Fulfillment | B37: =BvA!$J$22 -> -106602 | C37: =BvA!$K$22 -> -0.15461397 | D37: =MAX(B37,0) -> 0 | E37: =MIN(B37,0) -> -106602
A38: =BvA!$A$28 -> Salaries & Benefits | B38: =BvA!$J$28 -> 64100 | C38: =BvA!$K$28 -> 0.024500248 | D38: =MAX(B38,0) -> 64100 | E38: =MIN(B38,0) -> 0
A39: =BvA!$A$29 -> Marketing & Advertising | B39: =BvA!$J$29 -> -102756 | C39: =BvA!$K$29 -> -0.074517892 | D39: =MAX(B39,0) -> 0 | E39: =MIN(B39,0) -> -102756
A40: =BvA!$A$30 -> Rent & Utilities | B40: =BvA!$J$30 -> -6300 | C40: =BvA!$K$30 -> -0.011290323 | D40: =MAX(B40,0) -> 0 | E40: =MIN(B40,0) -> -6300
A41: =BvA!$A$31 -> Software & IT | B41: =BvA!$J$31 -> -33970 | C41: =BvA!$K$31 -> -0.099327485 | D41: =MAX(B41,0) -> 0 | E41: =MIN(B41,0) -> -33970
A42: =BvA!$A$32 -> Professional Fees | B42: =BvA!$J$32 -> -44800 | C42: =BvA!$K$32 -> -0.19227468 | D42: =MAX(B42,0) -> 0 | E42: =MIN(B42,0) -> -44800
A43: =BvA!$A$33 -> Travel & Entertainment | B43: =BvA!$J$33 -> 25600 | C43: =BvA!$K$33 -> 0.18962963 | D43: =MAX(B43,0) -> 25600 | E43: =MIN(B43,0) -> 0
A44: =BvA!$A$34 -> Insurance | B44: =BvA!$J$34 -> -2880 | C44: =BvA!$K$34 -> -0.026666667 | D44: =MAX(B44,0) -> 0 | E44: =MIN(B44,0) -> -2880
...

Sheet Commentary
A1: Variance Commentary
A2: Larkspur Home Goods, Inc. | Written at the September close (YTD Sep-26). Numbers are live links; text is as of that close.
A4: EXECUTIVE SUMMARY
A5: ="YTD revenue of "&TEXT(BvA!$I$17,"$#,##0")&" is "&TEXT(ABS(BvA!$K$17),"0.0%")&IF(BvA!$J$17>=0," ahead of"," behind")&" budget ("&TEXT(ABS(BvA!$J$17),"$#,##0")&"). Price contributed "&TEXT('Variance Analysis'!G9,"$#,##0;-$#,##0")&" and volume/mix "&TEXT('Variance Analysis'!F9,"$#,##0;-$#,##0")&"." -> YTD revenue of $15,479,960 is 1.0% ahead of budget ($158,360). Price contributed $14,612 and volume/mix $143,748.
A6: ="YTD EBITDA of "&TEXT(BvA!$I$37,"$#,##0")&" is "&TEXT(ABS(BvA!$J$37),"$#,##0")&" ("&TEXT(ABS(BvA!$K$37),"0.0%")&")"&IF(BvA!$J$37>=0," above"," below")&" budget; EBITDA margin is "&TEXT(BvA!$I$38,"0.0%")&" vs. "&TEXT(BvA!$H$38,"0.0%")&" budgeted." -> YTD EBITDA of $1,532,618 is $224,666 (12.8%) below budget; EBITDA margin is 9.9% vs. 11.5% budgeted.
A7: ="Gross margin of "&TEXT(BvA!$I$25,"0.0%")&" compares with "&TEXT(BvA!$H$25,"0.0%")&" in budget. COGS rate effects cost "&TEXT(-'Variance Analysis'!F18,"$#,##0;-$#,##0")&" (materials, overtime, freight) after adjusting for volume." -> Gross margin of 46.3% compares with 47.6% in budget. COGS rate effects cost $212,582 (materials, overtime, freight) after adjusting for volume.
A8: ="Full-year outlook (9+3): revenue "&TEXT(BvA!$P$17,"$#,##0")&" vs. budget "&TEXT(BvA!$O$17,"$#,##0")&"; EBITDA "&TEXT(BvA!$P$37,"$#,##0")&" vs. budget "&TEXT(BvA!$O$37,"$#,##0")&" ("&TEXT(BvA!$R$37,"0.0%;-0.0%")&")." -> Full-year outlook (9+3): revenue $23,440,686 vs. budget $23,040,000; EBITDA $3,060,196 vs. budget $3,353,650 (-8.8%).
A10: Line item | B10: YTD Budget | C10: YTD Actual | D10: Var $ | E10: Var % | F10: Status | G10: Driver type | H10: What happened | I10: Forecast treatment / action
A11: =BvA!$A$14 -> Kitchenware | B11: =BvA!$H$14 -> 5745600 | C11: =BvA!$I$14 -> 5989602 | D11: =BvA!$J$14 -> 244002 | E11: =BvA!$K$14 -> 0.042467627 | F11: =BvA!$L$14 -> Fav | G11: Price / Volume | H11: March promotional pricing (about 2-3% below list) lifted units well above plan from April onward. The volume gain more than offset the lower price. | I11: Promo pricing and +8% volume vs. budget carried through Q4. Review promo ROI before the FY2027 price file.
A12: =BvA!$A$15 -> Home Textiles | B12: =BvA!$H$15 -> 5187000 | C12: =BvA!$I$15 -> 4852498 | D12: =BvA!$J$15 -> -334502 | E12: =BvA!$K$15 -> -0.064488529 | F12: =BvA!$L$15 -> Unfav | G12: Volume (supply) | H12: A supplier delay caused stockouts in May and June, with units 14-20% below plan in those months. Volume recovered to within 3-5% of plan by August-September; pricing held. | I12: Forecast assumes -4% volume vs. budget in Q4. Second-source supplier qualified in August to reduce stockout risk.
A13: =BvA!$A$16 -> Home Decor & Lighting | B13: =BvA!$H$16 -> 4389000 | C13: =BvA!$I$16 -> 4637860 | D13: =BvA!$J$16 -> 248860 | E13: =BvA!$K$16 -> 0.056700843 | F13: =BvA!$L$16 -> Fav | G13: Price | H13: A 4% list price increase effective April held with no volume loss; units ran slightly ahead of plan. | I13: Higher price and +4% volume carried through Q4.
A14: =BvA!$A$20 -> Materials | B14: =BvA!$H$20 -> 5586000 | C14: =BvA!$I$20 -> 5709304 | D14: =BvA!$J$20 -> -123304 | E14: =BvA!$K$20 -> -0.022073756 | F14: =BvA!$L$20 -> Unfav | G14: Rate / Volume | H14: Cotton input costs rose about 7% from April, raising Home Textiles material cost per unit. Higher Kitchenware volume also added material spend, which is volume-driven rather than a cost overrun. | I14: Forecast keeps the higher textiles cost. Procurement is negotiating a 2027 fixed-price contract.
A15: =BvA!$A$21 -> Direct Labor | B15: =BvA!$H$21 -> 1755600 | C15: =BvA!$I$21 -> 1803614 | D15: =BvA!$J$21 -> -48014 | E15: =BvA!$K$21 -> -0.027349054 | F15: =BvA!$L$21 -> Unfav | G15: Efficiency | H15: Overtime in July and August to rebuild Home Textiles inventory after the supplier delay; labor per unit ran 6-7% above standard in those months. | I15: Overtime ended in September. Forecast carries 2% over standard.
A16: =BvA!$A$22 -> Freight & Fulfillment | B16: =BvA!$H$22 -> 689472 | C16: =BvA!$I$22 -> 796074 | D16: =BvA!$J$22 -> -106602 | E16: =BvA!$K$22 -> -0.15461397 | F16: =BvA!$L$22 -> Unfav | G16: Rate | H16: Carrier fuel surcharges from May, plus expedited inbound and customer shipments in June-July during the stockout recovery. Freight peaked near 6% of revenue vs. 4.5% budgeted. | I16: Forecast at 5.0% of revenue: surcharge stays, expediting stops. Carrier contract rebid planned for Q1 FY2027.
A17: =BvA!$A$28 -> Salaries & Benefits | B17: =BvA!$H$28 -> 2616300 | C17: =BvA!$I$28 -> 2552200 | D17: =BvA!$J$28 -> 64100 | E17: =BvA!$K$28 -> 0.024500248 | F17: =BvA!$L$28 -> Fav | G17: Timing / Headcount | H17: Two open roles in February-March produced savings in H1. Both were filled by July, and July onward also carries a higher benefits renewal, so the run-rate is now above budget. | I17: Forecast at $298K per month including holiday temp staff. The YTD favorability will partly reverse in Q4.
A18: =BvA!$A$29 -> Marketing & Advertising | B18: =BvA!$H$29 -> 1378944 | C18: =BvA!$I$29 -> 1481700 | D18: =BvA!$J$29 -> -102756 | E18: =BvA!$K$29 -> -0.074517892 | F18: =BvA!$L$29 -> Unfav | G18: Discretionary | H18: Unbudgeted spring campaign in March and a larger back-to-school push in August. Spend supported the Kitchenware volume gain. | I18: Q4 held at 9.2% of revenue. Any further campaign needs a payback case.
A19: =BvA!$A$31 -> Software & IT | B19: =BvA!$H$31 -> 342000 | C19: =BvA!$I$31 -> 375970 | D19: =BvA!$J$31 -> -33970 | E19: =BvA!$K$31 -> -0.099327485 | F19: =BvA!$L$31 -> Unfav | G19: Scope change | H19: Inventory planning module added in May (about $6.5K per month), approved after the Home Textiles stockouts. | I19: Run-rate of $44.7K per month carried forward. Permanent increase to build into the FY2027 budget.
A20: =BvA!$A$32 -> Professional Fees | B20: =BvA!$H$32 -> 233000 | C20: =BvA!$I$32 -> 277800 | D20: =BvA!$J$32 -> -44800 | E20: =BvA!$K$32 -> -0.19227468 | F20: =BvA!$L$32 -> Unfav | G20: One-time | H20: Legal fees for renegotiating the textiles supplier contract and recruiter fees for the two hires, mostly in June and July. | I20: Non-recurring. Forecast returns to about $24K per month.
A21: =BvA!$A$33 -> Travel & Entertainment | B21: =BvA!$H$33 -> 135000 | C21: =BvA!$I$33 -> 109400 | D21: =BvA!$J$33 -> 25600 | E21: =BvA!$K$33 -> 0.18962963 | F21: =BvA!$L$33 -> Fav | G21: Savings | H21: One trade show attended virtually and lower sales travel in Q2-Q3. | I21: Forecast at $13K per month, slightly below budget.
A22: =BvA!$A$30 -> Rent & Utilities | B22: =BvA!$H$30 -> 558000 | C22: =BvA!$I$30 -> 564300 | D22: =BvA!$J$30 -> -6300 | E22: =BvA!$K$30 -> -0.011290323 | F22: =BvA!$L$30 -> Unfav | G22: Contractual | H22: Lease renewal escalator effective July (+$2.1K per month). | I22: Carried in forecast.
A23: =BvA!$A$34 -> Insurance | B23: =BvA!$H$34 -> 108000 | C23: =BvA!$I$34 -> 110880 | D23: =BvA!$J$34 -> -2880 | E23: =BvA!$K$34 -> -0.026666667 | F23: =BvA!$L$34 -> Unfav | G23: Contractual | H23: Policy renewed in July at about 8% higher premium. | I23: Carried in forecast.
A24: =BvA!$A$35 -> Other G&A | B24: =BvA!$H$35 -> 162000 | C24: =BvA!$I$35 -> 166100 | D24: =BvA!$J$35 -> -4100 | E24: =BvA!$K$35 -> -0.025308642 | F24: =BvA!$L$35 -> Unfav | G24: Mixed | H24: Small month-to-month fluctuations; no single driver. | I24: Forecast at YTD average.

Sheet Forecast
A1: FY2026 Rolling Forecast (9+3)
A2: Larkspur Home Goods, Inc. | Closed months = actuals; open months = driver-based forecast from Assumptions
A3: Month # | B3: 1 | C3: 2 | D3: 3 | E3: 4 | F3: 5 | G3: 6 | H3: 7 | I3: 8 | J3: 9 | K3: 10 | L3: 11 | M3: 12
A4: ($ unless noted) | B4: Jan-26 | C4: Feb-26 | D4: Mar-26 | E4: Apr-26 | F4: May-26 | G4: Jun-26 | H4: Jul-26 | I4: Aug-26 | J4: Sep-26 | K4: Oct-26 | L4: Nov-26 | M4: Dec-26 | N4: FY2026
A5: UNITS SOLD
A6: Kitchenware | B6: =IF(B$3<=Assumptions!$B$6,Actuals!B6,ROUND(Budget!B6*(1+Assumptions!$B$35),0)) -> 11817 | C6: =IF(C$3<=Assumptions!$B$6,Actuals!C6,ROUND(Budget!C6*(1+Assumptions!$B$35),0)) -> 11583 | D6: =IF(D$3<=Assumptions!$B$6,Actuals!D6,ROUND(Budget!D6*(1+Assumptions!$B$35),0)) -> 14040 | E6: =IF(E$3<=Assumptions!$B$6,Actuals!E6,ROUND(Budget!E6*(1+Assumptions!$B$35),0)) -> 14580 | F6: =IF(F$3<=Assumptions!$B$6,Actuals!F6,ROUND(Budget!F6*(1+Assumptions!$B$35),0)) -> 15696 | G6: =IF(G$3<=Assumptions!$B$6,Actuals!G6,ROUND(Budget!G6*(1+Assumptions!$B$35),0)) -> 14445 | H6: =IF(H$3<=Assumptions!$B$6,Actuals!H6,ROUND(Budget!H6*(1+Assumptions!$B$35),0)) -> 13608 | I6: =IF(I$3<=Assumptions!$B$6,Actuals!I6,ROUND(Budget!I6*(1+Assumptions!$B$35),0)) -> 14850 | ... M6: =IF(M$3<=Assumptions!$B$6,Actuals!M6,ROUND(Budget!M6*(1+Assumptions!$B$35),0)) -> 22356 | N6: =SUM(B6:M6) -> 192420
A7: Home Textiles | B7: =IF(B$3<=Assumptions!$B$6,Actuals!B7,ROUND(Budget!B7*(1+Assumptions!$B$36),0)) -> 7800 | C7: =IF(C$3<=Assumptions!$B$6,Actuals!C7,ROUND(Budget!C7*(1+Assumptions!$B$36),0)) -> 7644 | D7: =IF(D$3<=Assumptions!$B$6,Actuals!D7,ROUND(Budget!D7*(1+Assumptions!$B$36),0)) -> 8910 | E7: =IF(E$3<=Assumptions!$B$6,Actuals!E7,ROUND(Budget!E7*(1+Assumptions!$B$36),0)) -> 8730 | F7: =IF(F$3<=Assumptions!$B$6,Actuals!F7,ROUND(Budget!F7*(1+Assumptions!$B$36),0)) -> 8256 | G7: =IF(G$3<=Assumptions!$B$6,Actuals!G7,ROUND(Budget!G7*(1+Assumptions!$B$36),0)) -> 7200 | H7: =IF(H$3<=Assumptions!$B$6,Actuals!H7,ROUND(Budget!H7*(1+Assumptions!$B$36),0)) -> 7560 | I7: =IF(I$3<=Assumptions!$B$6,Actuals!I7,ROUND(Budget!I7*(1+Assumptions!$B$36),0)) -> 8550 | ... M7: =IF(M$3<=Assumptions!$B$6,Actuals!M7,ROUND(Budget!M7*(1+Assumptions!$B$36),0)) -> 13248 | N7: =SUM(B7:M7) -> 113136
A8: Home Decor & Lighting | B8: =IF(B$3<=Assumptions!$B$6,Actuals!B8,ROUND(Budget!B8*(1+Assumptions!$B$37),0)) -> 3861 | C8: =IF(C$3<=Assumptions!$B$6,Actuals!C8,ROUND(Budget!C8*(1+Assumptions!$B$37),0)) -> 3978 | D8: =IF(D$3<=Assumptions!$B$6,Actuals!D8,ROUND(Budget!D8*(1+Assumptions!$B$37),0)) -> 4635 | E8: =IF(E$3<=Assumptions!$B$6,Actuals!E8,ROUND(Budget!E8*(1+Assumptions!$B$37),0)) -> 4545 | F8: =IF(F$3<=Assumptions!$B$6,Actuals!F8,ROUND(Budget!F8*(1+Assumptions!$B$37),0)) -> 4944 | G8: =IF(G$3<=Assumptions!$B$6,Actuals!G8,ROUND(Budget!G8*(1+Assumptions!$B$37),0)) -> 4680 | H8: =IF(H$3<=Assumptions!$B$6,Actuals!H8,ROUND(Budget!H8*(1+Assumptions!$B$37),0)) -> 4326 | I8: =IF(I$3<=Assumptions!$B$6,Actuals!I8,ROUND(Budget!I8*(1+Assumptions!$B$37),0)) -> 4725 | ... M8: =IF(M$3<=Assumptions!$B$6,Actuals!M8,ROUND(Budget!M8*(1+Assumptions!$B$37),0)) -> 7176 | N8: =SUM(B8:M8) -> 61902
A9: Total Units | B9: =SUM(B6:B8) -> 23478 | C9: =SUM(C6:C8) -> 23205 | D9: =SUM(D6:D8) -> 27585 | E9: =SUM(E6:E8) -> 27855 | F9: =SUM(F6:F8) -> 28896 | G9: =SUM(G6:G8) -> 26325 | H9: =SUM(H6:H8) -> 25494 | I9: =SUM(I6:I8) -> 28125 | ... N9: =SUM(N6:N8) -> 367458
A11: REVENUE
A12: Kitchenware | B12: =IF(B$3<=Assumptions!$B$6,Actuals!B12,B6*Assumptions!$C$35) -> 567216 | C12: =IF(C$3<=Assumptions!$B$6,Actuals!C12,C6*Assumptions!$C$35) -> 555984 | D12: =IF(D$3<=Assumptions!$B$6,Actuals!D12,D6*Assumptions!$C$35) -> 653702 | E12: =IF(E$3<=Assumptions!$B$6,Actuals!E12,E6*Assumptions!$C$35) -> 678845 | F12: =IF(F$3<=Assumptions!$B$6,Actuals!F12,F6*Assumptions!$C$35) -> 738340 | G12: =IF(G$3<=Assumptions!$B$6,Actuals!G12,G6*Assumptions!$C$35) -> 679493 | H12: =IF(H$3<=Assumptions!$B$6,Actuals!H12,H6*Assumptions!$C$35) -> 640120 | I12: =IF(I$3<=Assumptions!$B$6,Actuals!I12,I6*Assumptions!$C$35) -> 691416 | ... M12: =IF(M$3<=Assumptions!$B$6,Actuals!M12,M6*Assumptions!$C$35) -> 1050732 | N12: =SUM(B12:M12) -> 9050430
A13: Home Textiles | B13: =IF(B$3<=Assumptions!$B$6,Actuals!B13,B7*Assumptions!$C$36) -> 507000 | C13: =IF(C$3<=Assumptions!$B$6,Actuals!C13,C7*Assumptions!$C$36) -> 496860 | D13: =IF(D$3<=Assumptions!$B$6,Actuals!D13,D7*Assumptions!$C$36) -> 579150 | E13: =IF(E$3<=Assumptions!$B$6,Actuals!E13,E7*Assumptions!$C$36) -> 573124 | F13: =IF(F$3<=Assumptions!$B$6,Actuals!F13,F7*Assumptions!$C$36) -> 536640 | G13: =IF(G$3<=Assumptions!$B$6,Actuals!G13,G7*Assumptions!$C$36) -> 472680 | H13: =IF(H$3<=Assumptions!$B$6,Actuals!H13,H7*Assumptions!$C$36) -> 491400 | I13: =IF(I$3<=Assumptions!$B$6,Actuals!I13,I7*Assumptions!$C$36) -> 555750 | ... M13: =IF(M$3<=Assumptions!$B$6,Actuals!M13,M7*Assumptions!$C$36) -> 861120 | N13: =SUM(B13:M13) -> 7360978
A14: Home Decor & Lighting | B14: =IF(B$3<=Assumptions!$B$6,Actuals!B14,B8*Assumptions!$C$37) -> 424710 | C14: =IF(C$3<=Assumptions!$B$6,Actuals!C14,C8*Assumptions!$C$37) -> 437580 | D14: =IF(D$3<=Assumptions!$B$6,Actuals!D14,D8*Assumptions!$C$37) -> 509850 | E14: =IF(E$3<=Assumptions!$B$6,Actuals!E14,E8*Assumptions!$C$37) -> 519948 | F14: =IF(F$3<=Assumptions!$B$6,Actuals!F14,F8*Assumptions!$C$37) -> 565594 | G14: =IF(G$3<=Assumptions!$B$6,Actuals!G14,G8*Assumptions!$C$37) -> 537966 | H14: =IF(H$3<=Assumptions!$B$6,Actuals!H14,H8*Assumptions!$C$37) -> 494894 | I14: =IF(I$3<=Assumptions!$B$6,Actuals!I14,I8*Assumptions!$C$37) -> 540540 | ... M14: =IF(M$3<=Assumptions!$B$6,Actuals!M14,M8*Assumptions!$C$37) -> 820934.4 | N14: =SUM(B14:M14) -> 7029277.6
A15: Total Revenue | B15: =SUM(B12:B14) -> 1498926 | C15: =SUM(C12:C14) -> 1490424 | D15: =SUM(D12:D14) -> 1742702 | E15: =SUM(E12:E14) -> 1771917 | F15: =SUM(F12:F14) -> 1840574 | G15: =SUM(G12:G14) -> 1690139 | H15: =SUM(H12:H14) -> 1626414 | I15: =SUM(I12:I14) -> 1787706 | ... N15: =SUM(N12:N14) -> 23440686
A17: COST OF GOODS SOLD
A18: Materials | B18: =IF(B$3<=Assumptions!$B$6,Actuals!B18,SUMPRODUCT(B6:B8,Assumptions!$D$35:$D$37)) -> 545964 | C18: =IF(C$3<=Assumptions!$B$6,Actuals!C18,SUMPRODUCT(C6:C8,Assumptions!$D$35:$D$37)) -> 543127 | D18: =IF(D$3<=Assumptions!$B$6,Actuals!D18,SUMPRODUCT(D6:D8,Assumptions!$D$35:$D$37)) -> 642069 | E18: =IF(E$3<=Assumptions!$B$6,Actuals!E18,SUMPRODUCT(E6:E8,Assumptions!$D$35:$D$37)) -> 653586 | F18: =IF(F$3<=Assumptions!$B$6,Actuals!F18,SUMPRODUCT(F6:F8,Assumptions!$D$35:$D$37)) -> 680909 | G18: =IF(G$3<=Assumptions!$B$6,Actuals!G18,SUMPRODUCT(G6:G8,Assumptions!$D$35:$D$37)) -> 621804 | H18: =IF(H$3<=Assumptions!$B$6,Actuals!H18,SUMPRODUCT(H6:H8,Assumptions!$D$35:$D$37)) -> 602303 | I18: =IF(I$3<=Assumptions!$B$6,Actuals!I18,SUMPRODUCT(I6:I8,Assumptions!$D$35:$D$37)) -> 665152 | ... M18: =IF(M$3<=Assumptions!$B$6,Actuals!M18,SUMPRODUCT(M6:M8,Assumptions!$D$35:$D$37)) -> 1013618.3 | N18: =SUM(B18:M18) -> 8662018.1
A19: Direct Labor | B19: =IF(B$3<=Assumptions!$B$6,Actuals!B19,SUMPRODUCT(B6:B8,Assumptions!$E$11:$E$13)*(1+Assumptions!$B$40)) -> 171678 | C19: =IF(C$3<=Assumptions!$B$6,Actuals!C19,SUMPRODUCT(C6:C8,Assumptions!$E$11:$E$13)*(1+Assumptions!$B$40)) -> 170781 | D19: =IF(D$3<=Assumptions!$B$6,Actuals!D19,SUMPRODUCT(D6:D8,Assumptions!$E$11:$E$13)*(1+Assumptions!$B$40)) -> 201735 | E19: =IF(E$3<=Assumptions!$B$6,Actuals!E19,SUMPRODUCT(E6:E8,Assumptions!$E$11:$E$13)*(1+Assumptions!$B$40)) -> 201825 | F19: =IF(F$3<=Assumptions!$B$6,Actuals!F19,SUMPRODUCT(F6:F8,Assumptions!$E$11:$E$13)*(1+Assumptions!$B$40)) -> 210888 | G19: =IF(G$3<=Assumptions!$B$6,Actuals!G19,SUMPRODUCT(G6:G8,Assumptions!$E$11:$E$13)*(1+Assumptions!$B$40)) -> 196385 | H19: =IF(H$3<=Assumptions!$B$6,Actuals!H19,SUMPRODUCT(H6:H8,Assumptions!$E$11:$E$13)*(1+Assumptions!$B$40)) -> 195843 | I19: =IF(I$3<=Assumptions!$B$6,Actuals!I19,SUMPRODUCT(I6:I8,Assumptions!$E$11:$E$13)*(1+Assumptions!$B$40)) -> 218360 | ... M19: =IF(M$3<=Assumptions!$B$6,Actuals!M19,SUMPRODUCT(M6:M8,Assumptions!$E$11:$E$13)*(1+Assumptions!$B$40)) -> 317273.04 | N19: =SUM(B19:M19) -> 2727844.2
A20: Freight & Fulfillment | B20: =IF(B$3<=Assumptions!$B$6,Actuals!B20,B15*Assumptions!$B$41) -> 67452 | C20: =IF(C$3<=Assumptions!$B$6,Actuals!C20,C15*Assumptions!$B$41) -> 68560 | D20: =IF(D$3<=Assumptions!$B$6,Actuals!D20,D15*Assumptions!$B$41) -> 81907 | E20: =IF(E$3<=Assumptions!$B$6,Actuals!E20,E15*Assumptions!$B$41) -> 85052 | F20: =IF(F$3<=Assumptions!$B$6,Actuals!F20,F15*Assumptions!$B$41) -> 95710 | G20: =IF(G$3<=Assumptions!$B$6,Actuals!G20,G15*Assumptions!$B$41) -> 103098 | H20: =IF(H$3<=Assumptions!$B$6,Actuals!H20,H15*Assumptions!$B$41) -> 95958 | I20: =IF(I$3<=Assumptions!$B$6,Actuals!I20,I15*Assumptions!$B$41) -> 94748 | ... M20: =IF(M$3<=Assumptions!$B$6,Actuals!M20,M15*Assumptions!$B$41) -> 136639.32 | N20: =SUM(B20:M20) -> 1194110.3
A21: Total COGS | B21: =SUM(B18:B20) -> 785094 | C21: =SUM(C18:C20) -> 782468 | D21: =SUM(D18:D20) -> 925711 | E21: =SUM(E18:E20) -> 940463 | F21: =SUM(F18:F20) -> 987507 | G21: =SUM(G18:G20) -> 921287 | H21: =SUM(H18:H20) -> 894104 | I21: =SUM(I18:I20) -> 978260 | ... N21: =SUM(N18:N20) -> 12583973
A22: Gross Profit | B22: =B15-B21 -> 713832 | C22: =C15-C21 -> 707956 | D22: =D15-D21 -> 816991 | E22: =E15-E21 -> 831454 | F22: =F15-F21 -> 853067 | G22: =G15-G21 -> 768852 | H22: =H15-H21 -> 732310 | I22: =I15-I21 -> 809446 | ... N22: =N15-N21 -> 10856713
A23: Gross Margin % | B23: =IF(B15=0,0,B22/B15) -> 0.47622898 | C23: =IF(C15=0,0,C22/C15) -> 0.47500309 | D23: =IF(D15=0,0,D22/D15) -> 0.46880706 | E23: =IF(E15=0,0,E22/E15) -> 0.46923981 | F23: =IF(F15=0,0,F22/F15) -> 0.46347878 | G23: =IF(G15=0,0,G22/G15) -> 0.4549046 | H23: =IF(H15=0,0,H22/H15) -> 0.45026051 | I23: =IF(I15=0,0,I22/I15) -> 0.45278474 | ... N23: =IF(N15=0,0,N22/N15) -> 0.4631568
A25: OPERATING EXPENSES
A26: Salaries & Benefits | B26: =IF(B$3<=Assumptions!$B$6,Actuals!B26,Assumptions!$B$42) -> 284100 | C26: =IF(C$3<=Assumptions!$B$6,Actuals!C26,Assumptions!$B$42) -> 272300 | D26: =IF(D$3<=Assumptions!$B$6,Actuals!D26,Assumptions!$B$42) -> 270450 | E26: =IF(E$3<=Assumptions!$B$6,Actuals!E26,Assumptions!$B$42) -> 279200 | F26: =IF(F$3<=Assumptions!$B$6,Actuals!F26,Assumptions!$B$42) -> 280150 | G26: =IF(G$3<=Assumptions!$B$6,Actuals!G26,Assumptions!$B$42) -> 283400 | H26: =IF(H$3<=Assumptions!$B$6,Actuals!H26,Assumptions!$B$42) -> 293100 | I26: =IF(I$3<=Assumptions!$B$6,Actuals!I26,Assumptions!$B$42) -> 294480 | ... M26: =IF(M$3<=Assumptions!$B$6,Actuals!M26,Assumptions!$B$42) -> 298000 | N26: =SUM(B26:M26) -> 3446200
A27: Marketing & Advertising | B27: =IF(B$3<=Assumptions!$B$6,Actuals!B27,B15*Assumptions!$B$43) -> 134800 | C27: =IF(C$3<=Assumptions!$B$6,Actuals!C27,C15*Assumptions!$B$43) -> 132100 | D27: =IF(D$3<=Assumptions!$B$6,Actuals!D27,D15*Assumptions!$B$43) -> 199100 | E27: =IF(E$3<=Assumptions!$B$6,Actuals!E27,E15*Assumptions!$B$43) -> 164900 | F27: =IF(F$3<=Assumptions!$B$6,Actuals!F27,F15*Assumptions!$B$43) -> 170900 | G27: =IF(G$3<=Assumptions!$B$6,Actuals!G27,G15*Assumptions!$B$43) -> 158600 | H27: =IF(H$3<=Assumptions!$B$6,Actuals!H27,H15*Assumptions!$B$43) -> 151000 | I27: =IF(I$3<=Assumptions!$B$6,Actuals!I27,I15*Assumptions!$B$43) -> 183500 | ... M27: =IF(M$3<=Assumptions!$B$6,Actuals!M27,M15*Assumptions!$B$43) -> 251416.35 | N27: =SUM(B27:M27) -> 2214086.8
A28: Rent & Utilities | B28: =IF(B$3<=Assumptions!$B$6,Actuals!B28,Assumptions!$B$44) -> 62000 | C28: =IF(C$3<=Assumptions!$B$6,Actuals!C28,Assumptions!$B$44) -> 62000 | D28: =IF(D$3<=Assumptions!$B$6,Actuals!D28,Assumptions!$B$44) -> 62000 | E28: =IF(E$3<=Assumptions!$B$6,Actuals!E28,Assumptions!$B$44) -> 62000 | F28: =IF(F$3<=Assumptions!$B$6,Actuals!F28,Assumptions!$B$44) -> 62000 | G28: =IF(G$3<=Assumptions!$B$6,Actuals!G28,Assumptions!$B$44) -> 62000 | H28: =IF(H$3<=Assumptions!$B$6,Actuals!H28,Assumptions!$B$44) -> 64100 | I28: =IF(I$3<=Assumptions!$B$6,Actuals!I28,Assumptions!$B$44) -> 64100 | ... M28: =IF(M$3<=Assumptions!$B$6,Actuals!M28,Assumptions!$B$44) -> 64100 | N28: =SUM(B28:M28) -> 756600
A29: Software & IT | B29: =IF(B$3<=Assumptions!$B$6,Actuals!B29,Assumptions!$B$45) -> 37600 | C29: =IF(C$3<=Assumptions!$B$6,Actuals!C29,Assumptions!$B$45) -> 38200 | D29: =IF(D$3<=Assumptions!$B$6,Actuals!D29,Assumptions!$B$45) -> 38400 | E29: =IF(E$3<=Assumptions!$B$6,Actuals!E29,Assumptions!$B$45) -> 38900 | F29: =IF(F$3<=Assumptions!$B$6,Actuals!F29,Assumptions!$B$45) -> 44500 | G29: =IF(G$3<=Assumptions!$B$6,Actuals!G29,Assumptions!$B$45) -> 44500 | H29: =IF(H$3<=Assumptions!$B$6,Actuals!H29,Assumptions!$B$45) -> 44650 | I29: =IF(I$3<=Assumptions!$B$6,Actuals!I29,Assumptions!$B$45) -> 44500 | ... M29: =IF(M$3<=Assumptions!$B$6,Actuals!M29,Assumptions!$B$45) -> 44700 | N29: =SUM(B29:M29) -> 510070
A30: Professional Fees | B30: =IF(B$3<=Assumptions!$B$6,Actuals!B30,Assumptions!$B$46+IF(B$3=Assumptions!$B$29,Assumptions!$B$28,0)) -> 21500 | C30: =IF(C$3<=Assumptions!$B$6,Actuals!C30,Assumptions!$B$46+IF(C$3=Assumptions!$B$29,Assumptions!$B$28,0)) -> 23100 | D30: =IF(D$3<=Assumptions!$B$6,Actuals!D30,Assumptions!$B$46+IF(D$3=Assumptions!$B$29,Assumptions!$B$28,0)) -> 22400 | E30: =IF(E$3<=Assumptions!$B$6,Actuals!E30,Assumptions!$B$46+IF(E$3=Assumptions!$B$29,Assumptions!$B$28,0)) -> 61000 | F30: =IF(F$3<=Assumptions!$B$6,Actuals!F30,Assumptions!$B$46+IF(F$3=Assumptions!$B$29,Assumptions!$B$28,0)) -> 24000 | G30: =IF(G$3<=Assumptions!$B$6,Actuals!G30,Assumptions!$B$46+IF(G$3=Assumptions!$B$29,Assumptions!$B$28,0)) -> 48500 | H30: =IF(H$3<=Assumptions!$B$6,Actuals!H30,Assumptions!$B$46+IF(H$3=Assumptions!$B$29,Assumptions!$B$28,0)) -> 31000 | I30: =IF(I$3<=Assumptions!$B$6,Actuals!I30,Assumptions!$B$46+IF(I$3=Assumptions!$B$29,Assumptions!$B$28,0)) -> 22800 | ... M30: =IF(M$3<=Assumptions!$B$6,Actuals!M30,Assumptions!$B$46+IF(M$3=Assumptions!$B$29,Assumptions!$B$28,0)) -> 24000 | N30: =SUM(B30:M30) -> 349800
A31: Travel & Entertainment | B31: =IF(B$3<=Assumptions!$B$6,Actuals!B31,Assumptions!$B$47) -> 11200 | C31: =IF(C$3<=Assumptions!$B$6,Actuals!C31,Assumptions!$B$47) -> 12500 | D31: =IF(D$3<=Assumptions!$B$6,Actuals!D31,Assumptions!$B$47) -> 16800 | E31: =IF(E$3<=Assumptions!$B$6,Actuals!E31,Assumptions!$B$47) -> 11000 | F31: =IF(F$3<=Assumptions!$B$6,Actuals!F31,Assumptions!$B$47) -> 12100 | G31: =IF(G$3<=Assumptions!$B$6,Actuals!G31,Assumptions!$B$47) -> 10400 | H31: =IF(H$3<=Assumptions!$B$6,Actuals!H31,Assumptions!$B$47) -> 9800 | I31: =IF(I$3<=Assumptions!$B$6,Actuals!I31,Assumptions!$B$47) -> 13000 | ... M31: =IF(M$3<=Assumptions!$B$6,Actuals!M31,Assumptions!$B$47) -> 13000 | N31: =SUM(B31:M31) -> 148400
A32: Insurance | B32: =IF(B$3<=Assumptions!$B$6,Actuals!B32,Assumptions!$B$48) -> 12000 | C32: =IF(C$3<=Assumptions!$B$6,Actuals!C32,Assumptions!$B$48) -> 12000 | D32: =IF(D$3<=Assumptions!$B$6,Actuals!D32,Assumptions!$B$48) -> 12000 | E32: =IF(E$3<=Assumptions!$B$6,Actuals!E32,Assumptions!$B$48) -> 12000 | F32: =IF(F$3<=Assumptions!$B$6,Actuals!F32,Assumptions!$B$48) -> 12000 | G32: =IF(G$3<=Assumptions!$B$6,Actuals!G32,Assumptions!$B$48) -> 12000 | H32: =IF(H$3<=Assumptions!$B$6,Actuals!H32,Assumptions!$B$48) -> 12960 | I32: =IF(I$3<=Assumptions!$B$6,Actuals!I32,Assumptions!$B$48) -> 12960 | ... M32: =IF(M$3<=Assumptions!$B$6,Actuals!M32,Assumptions!$B$48) -> 12960 | N32: =SUM(B32:M32) -> 149760
A33: Other G&A | B33: =IF(B$3<=Assumptions!$B$6,Actuals!B33,Assumptions!$B$49) -> 17400 | C33: =IF(C$3<=Assumptions!$B$6,Actuals!C33,Assumptions!$B$49) -> 18900 | D33: =IF(D$3<=Assumptions!$B$6,Actuals!D33,Assumptions!$B$49) -> 19600 | E33: =IF(E$3<=Assumptions!$B$6,Actuals!E33,Assumptions!$B$49) -> 16800 | F33: =IF(F$3<=Assumptions!$B$6,Actuals!F33,Assumptions!$B$49) -> 18200 | G33: =IF(G$3<=Assumptions!$B$6,Actuals!G33,Assumptions!$B$49) -> 20100 | H33: =IF(H$3<=Assumptions!$B$6,Actuals!H33,Assumptions!$B$49) -> 17700 | I33: =IF(I$3<=Assumptions!$B$6,Actuals!I33,Assumptions!$B$49) -> 18400 | ... M33: =IF(M$3<=Assumptions!$B$6,Actuals!M33,Assumptions!$B$49) -> 18500 | N33: =SUM(B33:M33) -> 221600
A34: Total Operating Expenses | B34: =SUM(B26:B33) -> 580600 | C34: =SUM(C26:C33) -> 571100 | D34: =SUM(D26:D33) -> 640750 | E34: =SUM(E26:E33) -> 645800 | F34: =SUM(F26:F33) -> 623850 | G34: =SUM(G26:G33) -> 639500 | H34: =SUM(H26:H33) -> 624310 | I34: =SUM(I26:I33) -> 653740 | ... N34: =SUM(N26:N33) -> 7796516.8
A35: EBITDA | B35: =B22-B34 -> 133232 | C35: =C22-C34 -> 136856 | D35: =D22-D34 -> 176241 | E35: =E22-E34 -> 185654 | F35: =F22-F34 -> 229217 | G35: =G22-G34 -> 129352 | H35: =H22-H34 -> 108000 | I35: =I22-I34 -> 155706 | ... N35: =N22-N34 -> 3060196.3
A36: EBITDA Margin % | B36: =IF(B15=0,0,B35/B15) -> 0.088884975 | C36: =IF(C15=0,0,C35/C15) -> 0.091823535 | D36: =IF(D15=0,0,D35/D15) -> 0.10113089 | E36: =IF(E15=0,0,E35/E15) -> 0.10477579 | F36: =IF(F15=0,0,F35/F15) -> 0.12453561 | G36: =IF(G15=0,0,G35/G15) -> 0.07653335 | H36: =IF(H15=0,0,H35/H15) -> 0.066403757 | I36: =IF(I15=0,0,I35/I15) -> 0.087098214 | ... N36: =IF(N15=0,0,N35/N15) -> 0.13055063
A37: Basis | B37: =IF(B$3<=Assumptions!$B$6,"Actual","Forecast") -> Actual | C37: =IF(C$3<=Assumptions!$B$6,"Actual","Forecast") -> Actual | D37: =IF(D$3<=Assumptions!$B$6,"Actual","Forecast") -> Actual | E37: =IF(E$3<=Assumptions!$B$6,"Actual","Forecast") -> Actual | F37: =IF(F$3<=Assumptions!$B$6,"Actual","Forecast") -> Actual | G37: =IF(G$3<=Assumptions!$B$6,"Actual","Forecast") -> Actual | H37: =IF(H$3<=Assumptions!$B$6,"Actual","Forecast") -> Actual | I37: =IF(I$3<=Assumptions!$B$6,"Actual","Forecast") -> Actual | ... M37: =IF(M$3<=Assumptions!$B$6,"Actual","Forecast") -> Forecast
A38: Shaded columns are forecast months.

Sheet Budget
A1: FY2026 Budget
A2: Larkspur Home Goods, Inc. | Driver-based, built from Assumptions
A3: Month # | B3: 1 | C3: 2 | D3: 3 | E3: 4 | F3: 5 | G3: 6 | H3: 7 | I3: 8 | J3: 9 | K3: 10 | L3: 11 | M3: 12
A4: ($ unless noted) | B4: Jan-26 | C4: Feb-26 | D4: Mar-26 | E4: Apr-26 | F4: May-26 | G4: Jun-26 | H4: Jul-26 | I4: Aug-26 | J4: Sep-26 | K4: Oct-26 | L4: Nov-26 | M4: Dec-26 | N4: FY2026
A5: UNITS SOLD
A6: Kitchenware | B6: =ROUND(Assumptions!$B$11*Assumptions!B$17,0) -> 11700 | C6: =ROUND(Assumptions!$B$11*Assumptions!C$17,0) -> 11700 | D6: =ROUND(Assumptions!$B$11*Assumptions!D$17,0) -> 13500 | E6: =ROUND(Assumptions!$B$11*Assumptions!E$17,0) -> 13500 | F6: =ROUND(Assumptions!$B$11*Assumptions!F$17,0) -> 14400 | G6: =ROUND(Assumptions!$B$11*Assumptions!G$17,0) -> 13500 | H6: =ROUND(Assumptions!$B$11*Assumptions!H$17,0) -> 12600 | I6: =ROUND(Assumptions!$B$11*Assumptions!I$17,0) -> 13500 | ... M6: =ROUND(Assumptions!$B$11*Assumptions!M$17,0) -> 20700 | N6: =SUM(B6:M6) -> 180000
A7: Home Textiles | B7: =ROUND(Assumptions!$B$12*Assumptions!B$17,0) -> 7800 | C7: =ROUND(Assumptions!$B$12*Assumptions!C$17,0) -> 7800 | D7: =ROUND(Assumptions!$B$12*Assumptions!D$17,0) -> 9000 | E7: =ROUND(Assumptions!$B$12*Assumptions!E$17,0) -> 9000 | F7: =ROUND(Assumptions!$B$12*Assumptions!F$17,0) -> 9600 | G7: =ROUND(Assumptions!$B$12*Assumptions!G$17,0) -> 9000 | H7: =ROUND(Assumptions!$B$12*Assumptions!H$17,0) -> 8400 | I7: =ROUND(Assumptions!$B$12*Assumptions!I$17,0) -> 9000 | ... M7: =ROUND(Assumptions!$B$12*Assumptions!M$17,0) -> 13800 | N7: =SUM(B7:M7) -> 120000
A8: Home Decor & Lighting | B8: =ROUND(Assumptions!$B$13*Assumptions!B$17,0) -> 3900 | C8: =ROUND(Assumptions!$B$13*Assumptions!C$17,0) -> 3900 | D8: =ROUND(Assumptions!$B$13*Assumptions!D$17,0) -> 4500 | E8: =ROUND(Assumptions!$B$13*Assumptions!E$17,0) -> 4500 | F8: =ROUND(Assumptions!$B$13*Assumptions!F$17,0) -> 4800 | G8: =ROUND(Assumptions!$B$13*Assumptions!G$17,0) -> 4500 | H8: =ROUND(Assumptions!$B$13*Assumptions!H$17,0) -> 4200 | I8: =ROUND(Assumptions!$B$13*Assumptions!I$17,0) -> 4500 | ... M8: =ROUND(Assumptions!$B$13*Assumptions!M$17,0) -> 6900 | N8: =SUM(B8:M8) -> 60000
A9: Total Units | B9: =SUM(B6:B8) -> 23400 | C9: =SUM(C6:C8) -> 23400 | D9: =SUM(D6:D8) -> 27000 | E9: =SUM(E6:E8) -> 27000 | F9: =SUM(F6:F8) -> 28800 | G9: =SUM(G6:G8) -> 27000 | H9: =SUM(H6:H8) -> 25200 | I9: =SUM(I6:I8) -> 27000 | ... N9: =SUM(N6:N8) -> 360000
A11: REVENUE
